Workbook

Sheet MARA
A1: CÓDIGO | B1: DESCRIPCIÓN | C1: EAN UMA | D1: UMA | E1: CONVERSIÓN CAMA / PQT | F1: CONVERSION PAL / CAM | G1: CONVERSION PAL / PQT | H1: __PowerAppsId__
A2: 5905005 | B2: JABON. SPA 90GR 10BLI | C2: 17750672000784 | D2: CJA | E2: 11 | F2: 6 | G2: 66 | H2: 7c9221e9-3d38-455d-a8c5-99100cdbf07e
A3: 5905006 | B3: JABON. SPA 90GR 4UND 12PCK | C3: 17750672000777 | D3: CJA | E3: 19 | F3: 7 | G3: 133 | H3: 9ed4e050-66a3-4cbc-a7eb-d6e87a741ee6
A4: 5905007 | B4: JABON. SPA 150GR 3UND 21PCK | C4: 17750672000760 | D4: CJA | E4: 11 | F4: 6 | G4: 66 | H4: a49a73c1-f94e-46b1-b9ef-9cb9a5d84ab7
A5: 5905008 | B5: JABON. SPA PREMIUM MIX 4UND 320GR 25PCK | C5: 17750672001422 | D5: CJA | E5: 8 | F5: 8 | G5: 64 | H5: 281e4bf3-ba22-4820-aacd-f6cb925a7ae3
A6: 5905009 | B6: JABON. SPA PREMIUM MIX 3UND 390GR 18PCK | C6: 17750672001408 | D6: CJA | E6: 16 | F6: 6 | G6: 96 | H6: 42d292df-03ff-4a85-b9aa-66d334dbbeca
A7: 5905010 | B7: JABON. SPA PREMIUM EXOT 3UND 390GR 18PCK | C7: 17750672001415 | D7: CJA | E7: 16 | F7: 6 | G7: 96 | H7: ddeb2234-2cdb-4528-bd02-518639f3d705
A8: 5905102 | B8: JABON. SPA REFRESCANT 90GR 60UND | C8: 17750672000722 | D8: CJA | E8: 19 | F8: 7 | G8: 133 | H8: 84a3146c-f69b-47fd-ae6d-f43e11867ea9
A9: 5905103 | B9: JABON. SPA REFRESCANT 150GR 72UND | C9: 17750672000678 | D9: CJA | E9: 11 | F9: 6 | G9: 66 | H9: c2aaa844-f089-44c5-91c7-c3ae0d26cb58
A10: 5905104 | B10: JABON. SPA REFRESCANT TRIPCK 450GR | C10: 17750672001187 | D10: CJA | E10: 12 | F10: 6 | G10: 72 | H10: b4563778-1863-4636-a76b-42997a529709
A11: 5905105 | B11: JABON. SPA PREMIUM REFRES 80GR 60UND | C11: 17750672001002 | D11: CJA | E11: 19 | F11: 8 | G11: 152 | H11: 10334ca6-6053-49f2-8822-a9983cef0376
A12: 5905106 | B12: JABON. SPA PREMIUM REFRES 130GR 72UND | C12: 17750672001064 | D12: CJA | E12: 8 | F12: 8 | G12: 64 | H12: 4a69cbf5-36aa-4347-86e0-12d0d26eebf0
A13: 5905107 | B13: JABON. SPA PREMI REFRES 3UND 390GR 18PCK | C13: 17750672001385 | D13: CJA | E13: 16 | F13: 6 | G13: 96 | H13: 0d616c6b-91a2-4c1c-b718-79c4ff23ba5d
... A41: 5905812 | B41: JABÓN SPA PREMIUM RADIANTE 115GR 72UND | C41: 17750672002801 | D41: CJA | E41: 8 | F41: 8 | G41: 64 | H41: f1b01acf-89c6-465c-a6e8-1c6e32fdb142
A42: 5905813 | B42: JABÓN SPA | D42: CJA | E42: 8 | F42: 8 | G42: 64 | H42: d517776e-5660-4807-974c-158c02cba6d8
A43: 5905814 | B43: JABÓN PREM HUMECT SPA 115GR 72U NO USAR | D43: CJA | E43: 8 | F43: 8 | G43: 64 | H43: 972c525b-ee98-42db-9106-c012276ea039
A44: 5905822 | B44: JABÓN PREMIUM HUMECTANTE SPA 115GR 72UND | C44: 17750672003020 | D44: CJA | E44: 8 | F44: 8 | G44: 64 | H44: dc04cb7c-5f5c-4bc0-8818-5f69754e65d2
A45: 5905903 | B45: JABON. SPA PREM VERANO 130GR 72UND | C45: 17750672001781 | D45: CJA | E45: 8 | F45: 8 | G45: 64 | H45: 520d35c6-a817-4f91-8695-55d3cfe5cd2c
A46: 8300003 | B46: LEJIA SAPOLIO ORIGINAL 5000G 4BOT | C46: 17751851027028 | D46: CJA | E46: 9 | F46: 3 | G46: 27 | H46: 5811de45-5af9-4c99-8fb5-311af318a233
A47: 8300013 | B47: LEJIA 4.63% ORIG SAPOLIO JC 5GL 1UND | C47: 7751851029292 | D47: UND | E47: 17 | F47: 2 | G47: 34 | H47: 587da3c0-f2ac-4ef2-881d-baa0dc48f6b2
A48: 8300014 | B48: HIPOCLO. SODIO 8% SAPOLIO JC 5GL 1UND | C48: 7751851029315 | D48: UND | E48: 17 | F48: 2 | G48: 34 | H48: 01775046-fe70-43a8-81c9-a4d04c04da5e
A49: 8300021 | B49: LEJIA ORIG.SAPOLIO 250GR + 34% 15UND | C49: 27751851021412 | D49: CJA | E49: 19 | F49: 6 | G49: 114 | H49: 3bbdb84b-d439-4e58-ada4-9f24b3e99619
A50: 8300022 | B50: LEJIA ORIG.SAPOLIO 500GR + 34% 15UND | C50: 27751851021429 | D50: CJA | E50: 13 | F50: 5 | G50: 65 | H50: 080597ab-4d39-4d4d-a33d-bbfe8f595fc9
A51: 8300023 | B51: LEJIA ORIG.SAPOLIO 1000GR + 10% 12UND | C51: 17751851017340 | D51: CJA | E51: 11 | F51: 4 | G51: 44 | H51: 4704b186-7b78-425a-bbed-cc3149172739
A52: 8300038 | B52: LEJ.SAP.HIPOCLORITO D/SODI.8% GRANELXKG | D52: KG | H52: ef811415-c739-4f6e-aa7d-604cd210b54e
A53: 8300041 | B53: LEJIA PROFESIONAL SAPOLIO 4.63% 5KG.4UND | C53: 17750243060643 | D53: CJA | E53: 9 | F53: 3 | G53: 27 | H53: 04eab122-2188-4a5e-8398-b5f27a5e189b
A54: 8300052 | B54: LEJIA SAPOLIO 5.25% 4KG.4UND EXP.TRI | C54: 17750243060735 | D54: CJA | E54: 9 | F54: 4 | G54: 36 | H54: 27eb09f8-1f06-418b-bc2d-c3584ae8ee6f
A55: 8300062 | B55: LEJIA SAPOLIO LAVANDA 640GR 15 UND | C55: 17750243066393 | D55: CJA | E55: 13 | F55: 5 | G55: 65 | H55: bb94aa17-67d9-4a4a-9c86-5dbf512a3ecb
A56: 8300073 | B56: LEJIA SAPOLIO ORIGINAL 670GR 15UND | C56: 17750243067819 | D56: CJA | E56: 13 | F56: 5 | G56: 65 | H56: 66ed9914-3cbe-4211-a090-a5d22889f378
A57: 8300074 | B57: LEJIA SAPOLIO ORIGINAL 1KG 12UND | C57: 17750243067826 | D57: CJA | E57: 11 | F57: 4 | G57: 44 | H57: c224db2a-705c-4eea-97e6-6135ba75e23e
A58: 8300079 | B58: LAVANDINA SAPOL.F.BLANC.RED.1L 12UND BOL | C58: 17750243073292 | D58: CJA | E58: 11 | F58: 4 | G58: 44 | H58: 1953bb10-5070-4ca2-bf5e-a841680fd6d7
A59: 8300080 | B59: LAVANDINA SAPOL.BLANC.RED.1893ML 6UN BOL | C59: 17750243073308 | D59: CJA | E59: 10 | F59: 4 | G59: 40 | H59: 1af3dde0-e5dd-4f2b-a8fb-2330e4faab5b
A60: 8300085 | B60: LEJIA PATITO ORIGINAL 370GR 15UND | C60: 17750243073353 | D60: CJA | E60: 19 | F60: 6 | G60: 114 | H60: d6a03feb-09a7-4cce-bd68-a2f08f6c45e4
A61: 8300089 | B61: LEJIA CLORO SAPOLIO ORIGINAL 400GR 15UND | C61: 17750243074077 | D61: CJA | E61: 19 | F61: 5 | G61: 95 | H61: f14eea4c-9e84-4e2b-b128-5334be0c8a43
A62: 8300091 | B62: LEJIA CLORO SAPOL ORIGINAL 1.16KG 12UND | C62: 17750243074091 | D62: CJA | E62: 11 | F62: 3 | G62: 33 | H62: 5e5f5c87-76bc-4247-ae87-12b73eafaaa5
A63: 8300093 | B63: LEJIA CLORO SAPOLIO ORIGINAL 5KG 4UND | C63: 27751851027025 | D63: CJA | E63: 9 | F63: 3 | G63: 27 | H63: 1abb80ab-2d11-4901-837a-7b61f972e2ca
A64: 8300095 | B64: LEJIA CLORO SAP. ORIG. 790GR 15UND. S/P | C64: 27750243074081 | D64: CJA | E64: 13 | F64: 4 | G64: 52 | H64: d64188a0-2d0e-4aad-bed0-1798f621f24f
... A194: 8305041 | B194: LAVAV.LIQ.UL LIMA LIMON SAP. 500ML 12FCO | C194: 17751851026465 | D194: CJA | E194: 16 | F194: 4 | G194: 64 | H194: 0a331e1e-dc70-4f80-8c9c-3515685cf8e1
A195: 8305051 | B195: LAVAV.LIQ.UL MANZANA SAP.1250ML+ESP.6UND | D195: CJA | E195: 20 | F195: 3 | G195: 60 | H195: eb23da16-7eaf-4c8e-afc9-4b5e3006d205
A196: 8305076 | B196: LAVAVAJILLA PATITO LIMÓN 1000G 6UND | C196: 17751851023396 | D196: CJA | E196: 8 | F196: 8 | G196: 64 | H196: 6daf671b-7022-43f2-8bfb-01a861f1b11b
...

Sheet sap
A1: Ubicación | B1: Tipo almacén | C1: Producto | D1: Descripción producto | E1: Lote | F1: FeCaduc/FePreferCons | G1: Tipo de stock | H1: Ctd.embalada (UMA) | I1: Un.medida alternat. | J1: Ctd. | K1: Fecha EM | L1: Documento | M1: Grupo consolidación | N1: Control de calidad | O1: Peso de carga | P1: __PowerAppsId__
A2: PP-07-001-1 | B2: PERP | C2: 8300013 | D2: LEJIA 4.63% ORIG SAPOLIO JC 5GL 1UND | E2: 2608045060 | F2: 46485 | G2: 1F | H2: 19 | I2: UND | J2: 19 | K2: 08.08.2026 | O2: 395.276 | P2: 51f2c59c-bd7b-4501-9c2e-229a7a27d82f
A3: PP-07-008-1 | B3: PERP | C3: 8300041 | D3: LEJIA PROFESIONAL SAPOLIO 4.63% 5KG.4UND | E3: 2607275060 | F3: 27/07/2027 | G3: 1F | H3: 22 | I3: CJA | J3: 88 | K3: 28.07.2026 | O3: 467.94 | P3: c579347c-65bf-4362-bf4d-b53021a0813c
A4: PP-15-042-1 | B4: PERP | C4: 8300110 | D4: LEJÍA I PATITO B CLORO 370G 15 UND | E4: 2605275060 | F4: 27/05/2027 | G4: 1F | H4: 36 | I4: CJA | J4: 540 | K4: 28.07.2026 | O4: 219.564 | P4: c2507bd9-4257-4c09-9713-8679666b7745
A5: PP-15-010-1 | B5: PERP | C5: 8300111 | D5: LEJÍA I PATITO B CLORO 650G 12 UND | E5: 2608245060 | F5: 24/08/2027 | G5: 1F | H5: 61 | I5: CJA | J5: 732 | K5: 25.08.2026 | O5: 511.851 | P5: b4919487-8935-46c2-b564-51d7001887e4
A6: PP-09-006-1 | B6: PERP | C6: 8300112 | D6: LEJÍA I PATITO B CLORO 1KG 12 UND | E6: 2607075060 | F6: 46575 | G6: 1F | H6: 44 | I6: CJA | J6: 528 | K6: 28.07.2026 | O6: 564.96 | P6: b8ce338d-6f14-4c94-934d-a3ffbccc84f6
A7: PP-15-033-1 | B7: PERP | C7: 8300113 | D7: LEJIA SAPOLIO CLORO B 400GR 15UND | E7: 2608105060 | F7: 46668 | G7: 1F | H7: 16 | I7: CJA | J7: 240 | K7: 28.08.2026 | O7: 104.784 | P7: 996e5039-2e37-4b4e-a710-5e405aaac412
A8: PP-08-047-1 | B8: PERP | C8: 8300115 | D8: LEJIA SAPOLIO CLORO B 1.16KG 12UND | E8: 2608065060 | F8: 46546 | G8: 1F | H8: 32 | I8: CJA | J8: 384 | K8: 07.08.2026 | O8: 473.472 | P8: 34988c58-9a14-4561-93bb-1698fd6e9fa9
A9: PP-08-048-1 | B9: PERP | C9: 8300115 | D9: LEJIA SAPOLIO CLORO B 1.16KG 12UND | E9: 2608055060 | F9: 46515 | G9: 1F | H9: 11 | I9: CJA | J9: 132 | K9: 07.08.2026 | O9: 162.756 | P9: 59cb97b9-f9d5-48f2-ac08-7f127eda5009
A10: PP-08-051-1 | B10: PERP | C10: 8300116 | D10: LEJIA SAPOLIO CLORO B 2.5KG 6UND | E10: 2608155060 | F10: 15/08/2027 | G10: 1F | H10: 6 | I10: CJA | J10: 36 | K10: 29.08.2026 | O10: 95.784 | P10: 584cde7d-4746-4c4f-aebb-b7870f9290d4
A11: PP-07-026-1 | B11: PERP | C11: 8300117 | D11: LEJIA SAPOLIO CLORO B 4.8 KG 4UND | E11: 2608215060 | F11: 21/08/2027 | G11: 1F | H11: 9 | I11: CJA | J11: 36 | K11: 21.08.2026 | O11: 183.735 | P11: 5317276b-7dac-4df9-84c9-4478c3ad9beb
A12: PP-07-027-1 | B12: PERP | C12: 8300117 | D12: LEJIA SAPOLIO CLORO B 4.8 KG 4UND | E12: 2608225060 | F12: 22/08/2027 | G12: 1F | H12: 27 | I12: CJA | J12: 108 | K12: 22.08.2026 | O12: 551.205 | P12: e0c57497-53bf-4d2f-9e22-2c598f2a6892
A13: PP-09-008-1 | B13: PERP | C13: 8300120 | D13: LEJIA SAPOLIO CLORO B 770GR 15UND | E13: 2608135060 | F13: 13/08/2027 | G13: 1F | H13: 46 | I13: CJA | J13: 690 | K13: 15.08.2026 | O13: 584.614 | P13: 0c61a65a-93d7-4e02-ae73-ae9645799174
A14: PP-09-009-1 | B14: PERP | C14: 8300120 | D14: LEJIA SAPOLIO CLORO B 770GR 15UND | E14: 2608055060 | F14: 46515 | G14: 1F | H14: 25 | I14: CJA | J14: 375 | K14: 31.08.2026 | O14: 317.725 | P14: 8a7d576d-23df-4b1a-9dbf-9c257cac8957
A15: PP-08-006-1 | B15: PERP | C15: 8301100 | D15: CEP DENTO LIMPIALEN RT SUAVE 14UND 6DSP | E15: 2605125060 | F15: 47457 | G15: 1F | H15: 45 | I15: CJA | J15: 3780 | K15: 28.07.2026 | O15: 103.95 | P15: 4e727f3e-ab43-41da-a1c6-d30f0d691972
A16: PP-08-010-1 | B16: PERP | C16: 8301101 | D16: CEP DENTO PREMIUM GRAB RT MED.14UND 6DSP | E16: 2608125060 | F16: 47460 | G16: 1F | H16: 68 | I16: CJA | J16: 5712 | K16: 15.08.2026 | O16: 157.08 | P16: 5c9d6561-906c-455f-9258-7b5fce48d5cb
A17: PP-08-009-1 | B17: PERP | C17: 8301102 | D17: CEP DENTO PREMIUM GRAB RT DUR.14UND 6DSP | E17: 2608145060 | F17: 14/08/2029 | G17: 1F | H17: 48 | I17: CJA | J17: 4032 | K17: 18.08.2026 | O17: 110.88 | P17: 6f268184-2667-4ee9-bf7e-081b6f4ea22e
A18: PP-08-004-1 | B18: PERP | C18: 8301104 | D18: CEP DENTO GALAXY NIÑOS 14UND 6DSP | E18: 2608175060 | F18: 17/08/2029 | G18: 1F | H18: 53 | I18: CJA | J18: 4452 | K18: 20.08.2026 | O18: 106 | P18: df5d184b-097e-4793-a57d-74bdf4547acf
A19: PP-08-018-1 | B19: PERP | C19: 8301105 | D19: ENJ.BUCAL DENTO MENTA NATURAL 250ML 12UN | E19: 2608205070 | F19: 20/08/2029 | G19: 1F | H19: 13 | I19: CJA | J19: 156 | K19: 25.08.2026 | O19: 48.1 | P19: 188631e7-7f47-4a49-bd56-8ce5f70c5e0e
A20: PP-08-019-1 | B20: PERP | C20: 8301106 | D20: ENJ.BUCAL DENTO GLACIAL 250ML 12UND | E20: 2608085070 | F20: 47338 | G20: 1F | H20: 139 | I20: CJA | J20: 1668 | K20: 18.08.2026 | O20: 514.3 | P20: 3bf770e8-e55c-449f-b775-fdb22b9291aa
A21: PP-08-020-1 | B21: PERP | C21: 8301108 | D21: ENJ.BUCAL DENTITO TUTI FRUTI 250ML 12UND | E21: 2608015070 | F21: 47126 | G21: 1F | H21: 25 | I21: CJA | J21: 300 | K21: 09.08.2026 | O21: 92.5 | P21: bfcb7d9e-1d22-4aec-99f1-f4b0f6033b41
A22: PP-08-017-1 | B22: PERP | C22: 8301109 | D22: ENJ.DENTITO CHICHA MORADA 250ML 12UND | E22: 2605215070 | F22: 21/05/2029 | G22: 1F | H22: 40 | I22: CJA | J22: 480 | K22: 27.08.2026 | O22: 148 | P22: ad7d628c-c036-4f6b-885b-50d196944963
A23: PP-08-008-1 | B23: PERP | C23: 8301256 | D23: CEP DENTO PREMIUM GRAB RT SUA14UND 6DSP | E23: 2607275060 | F23: 27/07/2029 | G23: 1F | H23: 40 | I23: CJA | J23: 3360 | K23: 05.08.2026 | O23: 92.4 | P23: 30598d3d-a61e-4cea-b7b7-0227c3d8af79
A24: PP-08-005-1 | B24: PERP | C24: 8301260 | D24: CEP DENTO LIMPIALEN RT MEDIO 14UND 6DSP | E24: 2608045060 | F24: 47216 | G24: 1F | H24: 49 | I24: CJA | J24: 4116 | K24: 12.08.2026 | O24: 113.19 | P24: c01e8691-3e35-463f-8930-a491b0eeb510
A25: PP-08-016-1 | B25: PERP | C25: 8301271 | D25: CEP DENTO LIMPIALEN ZZ MED.X3 8BLS 6DSP | E25: 2606225060 | F25: 22/06/2029 | G25: 1F | H25: 11 | I25: CJA | J25: 528 | K25: 13.08.2026 | O25: 37.488 | P25: b8d98e97-35bb-4323-be14-6e076e1799a4
A26: PP-08-014-1 | B26: PERP | C26: 8301272 | D26: CEP DENTO LIMPIALEN ZZ DURO X3 8BLS 6DSP | E26: 2506235060 | F26: 23/06/2028 | G26: 1F | H26: 12 | I26: CJA | J26: 576 | K26: 29.08.2026 | O26: 40.896 | P26: dda1bbe7-de68-4a64-8515-b9724d56c2e3
A27: PP-08-015-1 | B27: PERP | C27: 8301274 | D27: CEP DENTO LIMPIALEN ZZ SUAV.X3 8BLS 6DSP | E27: 2603045060 | F27: 47211 | G27: 1F | H27: 8 | I27: CJA | J27: 384 | K27: 13.08.2026 | O27: 27.264 | P27: 2b1cb4fe-bc98-4e38-bbbb-74754353b766
A28: PP-08-043-1 | B28: PERP | C28: 8303001 | D28: DET LÍQ LAVAROPA FLORES SAP.1000ML 12UND | E28: 2607015060 | F28: 46759 | G28: 1F | H28: 33 | I28: CJA | J28: 396 | K28: 28.07.2026 | O28: 448.734 | P28: 2fe1ee11-1bdd-437b-92de-fce575740c1a
A29: PP-08-039-1 | B29: PERP | C29: 8303003 | D29: DETER.SAPO LIQ.LAVARO LIMON 2000ML 6UND | E29: 2607235060 | F29: 23/07/2028 | G29: 1F | H29: 27 | I29: CJA | J29: 162 | K29: 01.08.2026 | O29: 356.4 | P29: 252dd454-b14d-4e7b-a2c7-e9e88bfb6364
A30: PP-08-042-1 | B30: PERP | C30: 8303004 | D30: DET LÍQ LAVAROPA FLORES SAP.2000ML 6UN | E30: 2606085060 | F30: 46971 | G30: 1F | H30: 2 | I30: CJA | J30: 12 | K30: 28.08.2026 | O30: 26.556 | P30: 6795a590-1d2a-4afb-9e72-77857e7f9579
A31: PP-07-004-1 | B31: PERP | C31: 8303007 | D31: DET.LIQUIDO FRESCO LIMON SAP. 5L 4UND | E31: 2606045060 | F31: 46849 | G31: 1F | H31: 7 | I31: CJA | J31: 28 | K31: 28.07.2026 | O31: 154.35 | P31: d0a246bd-048a-4114-9bd4-96d5769981d6
A32: PP-07-014-1 | B32: PERP | C32: 8303008 | D32: DET.LIQUIDO FERIA DE FLORES SAP. 5L 4UND | E32: 2608195060 | F32: 19/08/2028 | G32: 1F | H32: 27 | I32: CJA | J32: 108 | K32: 25.08.2026 | O32: 602.262 | P32: d4d62356-eb45-4266-b674-013171024be2
A33: PP-12-041-1 | B33: PERP | C33: 8303020 | D33: DETERG.AMDC/ASA FLORAL SAPOLIO 6KG 2UND | E33: 2607025030 | F33: 47156 | G33: 1F | H33: 13 | I33: PQT | J33: 26 | K33: 28.07.2026 | O33: 158.08 | P33: 66466d45-69aa-4d4d-b12d-97560c14324a
A34: PP-11-019-1 | B34: PERP | C34: 8303023 | D34: DETER.SAPOLIO AMD C/ASA BEBE 8KG 2UND | E34: 2604115030 | F34: 47426 | G34: 1F | H34: 13 | I34: PQT | J34: 26 | K34: 28.07.2026 | O34: 210.548 | P34: ae23e357-2f7c-41b1-96f6-21cd41c85dfb
A35: PP-11-004-1 | B35: PERP | C35: 8303025 | D35: DETERG.AMDC/ASALIMON SAPOLIO 4000GR 4UND | E35: 2608030120 | F35: 47185 | G35: 1F | H35: 28 | I35: PQT | J35: 112 | K35: 30.08.2026 | O35: 456.624 | P35: 7831359f-d430-4150-8407-3e975be0ba18
A36: PP-11-005-1 | B36: PERP | C36: 8303028 | D36: DETER.SAPOLIO AMD C/ASA BEBE 4000GR 4UND | E36: 2608285030 | F36: 28/08/2029 | G36: 1F | H36: 13 | I36: PQT | J36: 52 | K36: 29.08.2026 | O36: 211.991 | P36: 13eedc99-3757-4412-9ead-38105b4bac6d
A37: PP-12-047-1 | B37: PERP | C37: 8303029 | D37: DET.SAP.LIMON 2KG.6UND | E37: 2608030120 | F37: 47185 | G37: 1F | H37: 31 | I37: PQT | J37: 186 | K37: 29.08.2026 | O37: 385.919 | P37: 4ddd8b19-9a9e-4ef5-ba57-283c14a5b5fd
A38: PP-12-044-1 | B38: PERP | C38: 8303031 | D38: DET.SAP.FLORAL 2KG.6UND | E38: 2608275030 | F38: 27/08/2029 | G38: 1F | H38: 33 | I38: PQT | J38: 198 | K38: 29.08.2026 | O38: 404.25 | P38: 5884d100-9273-4d69-884e-407680a3f922
A39: PP-11-047-1 | B39: PERP | C39: 8303032 | D39: DET.SAP.BEBE 2KG.6UND | E39: 2608180120 | F39: 18/08/2029 | G39: 1F | H39: 17 | I39: PQT | J39: 102 | K39: 19.08.2026 | O39: 222.7 | P39: be24e65d-8627-4b18-9afb-47faa4fd2bd8
A40: PP-11-048-1 | B40: PERP | C40: 8303032 | D40: DET.SAP.BEBE 2KG.6UND | E40: 2608180120 | F40: 18/08/2029 | G40: 1F | H40: 13 | I40: PQT | J40: 78 | K40: 19.08.2026 | O40: 170.3 | P40: 9d794e02-2515-43b3-907b-a67dadd9b5c0
...

Sheet CANTIDAD
A1: PASILLO | B1: Ubicación | C1: Producto | D1: EAN | E1: Descripción producto | F1: CANT. | G1: UMA CANT. | H1: Lote | I1: FeCaduc/FePreferCons | J1: Tipo de stock | K1: Ctd. | L1: CAMA | M1: UMA | N1: __PowerAppsId__
A2: ="PASILLO " & VALUE(MID(B2, 4, 2)) -> PASILLO 1 | B2: AP-01-005-1 | C2: =IFERROR(VLOOKUP(CANTIDAD[[#This Row],[Ubicación]],SAP[],3,FALSE),"") -> 8325056 | D2: =IFERROR(VLOOKUP(CANTIDAD[[#This Row],[Producto]],MARA[],3,FALSE),"") -> 37751851006645 | E2: =IFERROR(VLOOKUP(CANTIDAD[[#This Row],[Ubicación]],SAP[],4,FALSE),"") -> INSEC.CASA&JARDIN SAPOLIO 2A 360ML 12UND | F2: =IFERROR(VLOOKUP(CANTIDAD[[#This Row],[Ubicación]],SAP[],8,FALSE),"") -> 5 | G2: =IFERROR(VLOOKUP(CANTIDAD[[#This Row],[Ubicación]],SAP[],9,FALSE),"") -> CJA | H2: =IFERROR(VLOOKUP(CANTIDAD[[#This Row],[Ubicación]],SAP[],5,FALSE),"") -> 2601205060 | I2: =IFERROR(VLOOKUP(CANTIDAD[[#This Row],[Ubicación]],SAP[],6,FALSE),"") -> 20/01/2028 | J2: =IFERROR(VLOOKUP(CANTIDAD[[#This Row],[Ubicación]],SAP[],7,FALSE),"") -> 1F | K2: =IFERROR(VLOOKUP(CANTIDAD[[#This Row],[Ubicación]],SAP[],10,FALSE),"") -> 60 | L2: =IFERROR(VLOOKUP(CANTIDAD[[#This Row],[Producto]],MARA[],5,FALSE),"") -> 26 | M2: =IFERROR(VLOOKUP(CANTIDAD[[#This Row],[Producto]],MARA[],4,FALSE),"") -> CJA | N2: eb6e5dc7-cdbb-41ce-a519-9db63379b734
A3: ="PASILLO " & VALUE(MID(B3, 4, 2)) -> PASILLO 1 | B3: AP-01-006-1 | C3: =IFERROR(VLOOKUP(CANTIDAD[[#This Row],[Ubicación]],SAP[],3,FALSE),"") -> 8325096 | D3: =IFERROR(VLOOKUP(CANTIDAD[[#This Row],[Producto]],MARA[],3,FALSE),"") -> 37751851006652 | E3: =IFERROR(VLOOKUP(CANTIDAD[[#This Row],[Ubicación]],SAP[],4,FALSE),"") -> INSEC.MATAPOLILLAS SAPOLIO 2A 360ML 12UN | F3: =IFERROR(VLOOKUP(CANTIDAD[[#This Row],[Ubicación]],SAP[],8,FALSE),"") -> 9 | G3: =IFERROR(VLOOKUP(CANTIDAD[[#This Row],[Ubicación]],SAP[],9,FALSE),"") -> CJA | H3: =IFERROR(VLOOKUP(CANTIDAD[[#This Row],[Ubicación]],SAP[],5,FALSE),"") -> 2607215060 | I3: =IFERROR(VLOOKUP(CANTIDAD[[#This Row],[Ubicación]],SAP[],6,FALSE),"") -> 21/07/2028 | J3: =IFERROR(VLOOKUP(CANTIDAD[[#This Row],[Ubicación]],SAP[],7,FALSE),"") -> 1F | K3: =IFERROR(VLOOKUP(CANTIDAD[[#This Row],[Ubicación]],SAP[],10,FALSE),"") -> 108 | L3: =IFERROR(VLOOKUP(CANTIDAD[[#This Row],[Producto]],MARA[],5,FALSE),"") -> 26 | M3: =IFERROR(VLOOKUP(CANTIDAD[[#This Row],[Producto]],MARA[],4,FALSE),"") -> CJA | N3: bf79d15c-aead-4215-ab87-f93820c18ac9
A4: ="PASILLO " & VALUE(MID(B4, 4, 2)) -> PASILLO 1 | B4: AP-01-007-1 | C4: =IFERROR(VLOOKUP(CANTIDAD[[#This Row],[Ubicación]],SAP[],3,FALSE),"") -> 8315030 | D4: =IFERROR(VLOOKUP(CANTIDAD[[#This Row],[Producto]],MARA[],3,FALSE),"") -> 27751851006129 | E4: =IFERROR(VLOOKUP(CANTIDAD[[#This Row],[Ubicación]],SAP[],4,FALSE),"") -> LIMPIAHORNOS SAPOLIO 360ML 12UND | F4: =IFERROR(VLOOKUP(CANTIDAD[[#This Row],[Ubicación]],SAP[],8,FALSE),"") -> 39 | G4: =IFERROR(VLOOKUP(CANTIDAD[[#This Row],[Ubicación]],SAP[],9,FALSE),"") -> CJA | H4: =IFERROR(VLOOKUP(CANTIDAD[[#This Row],[Ubicación]],SAP[],5,FALSE),"") -> 2606235060 | I4: =IFERROR(VLOOKUP(CANTIDAD[[#This Row],[Ubicación]],SAP[],6,FALSE),"") -> 23/06/2029 | J4: =IFERROR(VLOOKUP(CANTIDAD[[#This Row],[Ubicación]],SAP[],7,FALSE),"") -> 1F | K4: =IFERROR(VLOOKUP(CANTIDAD[[#This Row],[Ubicación]],SAP[],10,FALSE),"") -> 468 | L4: =IFERROR(VLOOKUP(CANTIDAD[[#This Row],[Producto]],MARA[],5,FALSE),"") -> 26 | M4: =IFERROR(VLOOKUP(CANTIDAD[[#This Row],[Producto]],MARA[],4,FALSE),"") -> CJA | N4: 56647ca4-6783-4baa-891e-d0534a8178df
A5: ="PASILLO " & VALUE(MID(B5, 4, 2)) -> PASILLO 1 | B5: AP-01-008-1 | C5: =IFERROR(VLOOKUP(CANTIDAD[[#This Row],[Ubicación]],SAP[],3,FALSE),"") -> 8315000 | D5: =IFERROR(VLOOKUP(CANTIDAD[[#This Row],[Producto]],MARA[],3,FALSE),"") -> 17751851007556 | E5: =IFERROR(VLOOKUP(CANTIDAD[[#This Row],[Ubicación]],SAP[],4,FALSE),"") -> LUSTRAMUEBLE LAVANDA PREMIO 360ML 12UND | F5: =IFERROR(VLOOKUP(CANTIDAD[[#This Row],[Ubicación]],SAP[],8,FALSE),"") -> 15 | G5: =IFERROR(VLOOKUP(CANTIDAD[[#This Row],[Ubicación]],SAP[],9,FALSE),"") -> CJA | H5: =IFERROR(VLOOKUP(CANTIDAD[[#This Row],[Ubicación]],SAP[],5,FALSE),"") -> 2608175060 | I5: =IFERROR(VLOOKUP(CANTIDAD[[#This Row],[Ubicación]],SAP[],6,FALSE),"") -> 17/08/2028 | J5: =IFERROR(VLOOKUP(CANTIDAD[[#This Row],[Ubicación]],SAP[],7,FALSE),"") -> 1F | K5: =IFERROR(VLOOKUP(CANTIDAD[[#This Row],[Ubicación]],SAP[],10,FALSE),"") -> 180 | L5: =IFERROR(VLOOKUP(CANTIDAD[[#This Row],[Producto]],MARA[],5,FALSE),"") -> 26 | M5: =IFERROR(VLOOKUP(CANTIDAD[[#This Row],[Producto]],MARA[],4,FALSE),"") -> CJA | N5: 2f444ee8-6d2d-4f83-a7ae-0eb2397a2f8e
A6: ="PASILLO " & VALUE(MID(B6, 4, 2)) -> PASILLO 1 | B6: AP-01-009-1 | C6: =IFERROR(VLOOKUP(CANTIDAD[[#This Row],[Ubicación]],SAP[],3,FALSE),"") -> 8315001 | D6: =IFERROR(VLOOKUP(CANTIDAD[[#This Row],[Producto]],MARA[],3,FALSE),"") -> 17751851007563 | E6: =IFERROR(VLOOKUP(CANTIDAD[[#This Row],[Ubicación]],SAP[],4,FALSE),"") -> LUSTRAMUEBLE LIMON PREMIO 360ML 12UND | F6: =IFERROR(VLOOKUP(CANTIDAD[[#This Row],[Ubicación]],SAP[],8,FALSE),"") -> 57 | G6: =IFERROR(VLOOKUP(CANTIDAD[[#This Row],[Ubicación]],SAP[],9,FALSE),"") -> CJA | H6: =IFERROR(VLOOKUP(CANTIDAD[[#This Row],[Ubicación]],SAP[],5,FALSE),"") -> 2608045060 | I6: =IFERROR(VLOOKUP(CANTIDAD[[#This Row],[Ubicación]],SAP[],6,FALSE),"") -> 46851 | J6: =IFERROR(VLOOKUP(CANTIDAD[[#This Row],[Ubicación]],SAP[],7,FALSE),"") -> 1F | K6: =IFERROR(VLOOKUP(CANTIDAD[[#This Row],[Ubicación]],SAP[],10,FALSE),"") -> 684 | L6: =IFERROR(VLOOKUP(CANTIDAD[[#This Row],[Producto]],MARA[],5,FALSE),"") -> 26 | M6: =IFERROR(VLOOKUP(CANTIDAD[[#This Row],[Producto]],MARA[],4,FALSE),"") -> CJA | N6: b07e50f8-9315-4b9e-b0c8-cc043904071c
A7: ="PASILLO " & VALUE(MID(B7, 4, 2)) -> PASILLO 1 | B7: AP-01-010-1 | C7: =IFERROR(VLOOKUP(CANTIDAD[[#This Row],[Ubicación]],SAP[],3,FALSE),"") -> 8325116 | D7: =IFERROR(VLOOKUP(CANTIDAD[[#This Row],[Producto]],MARA[],3,FALSE),"") -> 47751851011196 | E7: =IFERROR(VLOOKUP(CANTIDAD[[#This Row],[Ubicación]],SAP[],4,FALSE),"") -> INSEC. MATA ACAROS SAPOLIO RE 360ML 12UN | F7: =IFERROR(VLOOKUP(CANTIDAD[[#This Row],[Ubicación]],SAP[],8,FALSE),"") -> 76 | G7: =IFERROR(VLOOKUP(CANTIDAD[[#This Row],[Ubicación]],SAP[],9,FALSE),"") -> CJA | H7: =IFERROR(VLOOKUP(CANTIDAD[[#This Row],[Ubicación]],SAP[],5,FALSE),"") -> 2608175060 | I7: =IFERROR(VLOOKUP(CANTIDAD[[#This Row],[Ubicación]],SAP[],6,FALSE),"") -> 17/08/2028 | J7: =IFERROR(VLOOKUP(CANTIDAD[[#This Row],[Ubicación]],SAP[],7,FALSE),"") -> 1F | K7: =IFERROR(VLOOKUP(CANTIDAD[[#This Row],[Ubicación]],SAP[],10,FALSE),"") -> 912 | L7: =IFERROR(VLOOKUP(CANTIDAD[[#This Row],[Producto]],MARA[],5,FALSE),"") -> 26 | M7: =IFERROR(VLOOKUP(CANTIDAD[[#This Row],[Producto]],MARA[],4,FALSE),"") -> CJA | N7: 86660267-3bff-4639-990e-ebfe8586daf3
A8: ="PASILLO " & VALUE(MID(B8, 4, 2)) -> PASILLO 1 | B8: AP-01-011-1 | C8: =IFERROR(VLOOKUP(CANTIDAD[[#This Row],[Ubicación]],SAP[],3,FALSE),"") -> 8325118 | D8: =IFERROR(VLOOKUP(CANTIDAD[[#This Row],[Producto]],MARA[],3,FALSE),"") -> 47751851006666 | E8: =IFERROR(VLOOKUP(CANTIDAD[[#This Row],[Ubicación]],SAP[],4,FALSE),"") -> INSEC MATA TERMITAS SAPOLIO RE 360ML12UN | F8: =IFERROR(VLOOKUP(CANTIDAD[[#This Row],[Ubicación]],SAP[],8,FALSE),"") -> 76 | G8: =IFERROR(VLOOKUP(CANTIDAD[[#This Row],[Ubicación]],SAP[],9,FALSE),"") -> CJA | H8: =IFERROR(VLOOKUP(CANTIDAD[[#This Row],[Ubicación]],SAP[],5,FALSE),"") -> 2608245060 | I8: =IFERROR(VLOOKUP(CANTIDAD[[#This Row],[Ubicación]],SAP[],6,FALSE),"") -> 24/08/2028 | J8: =IFERROR(VLOOKUP(CANTIDAD[[#This Row],[Ubicación]],SAP[],7,FALSE),"") -> 1F | K8: =IFERROR(VLOOKUP(CANTIDAD[[#This Row],[Ubicación]],SAP[],10,FALSE),"") -> 912 | L8: =IFERROR(VLOOKUP(CANTIDAD[[#This Row],[Producto]],MARA[],5,FALSE),"") -> 26 | M8: =IFERROR(VLOOKUP(CANTIDAD[[#This Row],[Producto]],MARA[],4,FALSE),"") -> CJA | N8: 6c13cb54-22ce-4c19-b500-f8fc16c234e7
A9: ="PASILLO " & VALUE(MID(B9, 4, 2)) -> PASILLO 1 | B9: AP-01-012-1 | C9: =IFERROR(VLOOKUP(CANTIDAD[[#This Row],[Ubicación]],SAP[],3,FALSE),"") -> 8309033 | D9: =IFERROR(VLOOKUP(CANTIDAD[[#This Row],[Producto]],MARA[],3,FALSE),"") -> 17751851019634 | E9: =IFERROR(VLOOKUP(CANTIDAD[[#This Row],[Ubicación]],SAP[],4,FALSE),"") -> PERFU.RPTO V/FRANCESA SAPOLIO 240ML 12UN | F9: =IFERROR(VLOOKUP(CANTIDAD[[#This Row],[Ubicación]],SAP[],8,FALSE),"") -> 50 | G9: =IFERROR(VLOOKUP(CANTIDAD[[#This Row],[Ubicación]],SAP[],9,FALSE),"") -> CJA | H9: =IFERROR(VLOOKUP(CANTIDAD[[#This Row],[Ubicación]],SAP[],5,FALSE),"") -> 2607205060 | I9: =IFERROR(VLOOKUP(CANTIDAD[[#This Row],[Ubicación]],SAP[],6,FALSE),"") -> 20/07/2029 | J9: =IFERROR(VLOOKUP(CANTIDAD[[#This Row],[Ubicación]],SAP[],7,FALSE),"") -> 1F | K9: =IFERROR(VLOOKUP(CANTIDAD[[#This Row],[Ubicación]],SAP[],10,FALSE),"") -> 600 | L9: =IFERROR(VLOOKUP(CANTIDAD[[#This Row],[Producto]],MARA[],5,FALSE),"") -> 18 | M9: =IFERROR(VLOOKUP(CANTIDAD[[#This Row],[Producto]],MARA[],4,FALSE),"") -> CJA | N9: 8d3996ca-5273-4b86-957d-4630e9ca50f2
A10: ="PASILLO " & VALUE(MID(B10, 4, 2)) -> PASILLO 1 | B10: AP-01-013-1 | C10: =IFERROR(VLOOKUP(CANTIDAD[[#This Row],[Ubicación]],SAP[],3,FALSE),"") -> 8325095 | D10: =IFERROR(VLOOKUP(CANTIDAD[[#This Row],[Producto]],MARA[],3,FALSE),"") -> 37751851006638 | E10: =IFERROR(VLOOKUP(CANTIDAD[[#This Row],[Ubicación]],SAP[],4,FALSE),"") -> INSEC.MATAPULGAS SAPOLIO 2A 360ML 12UND | F10: =IFERROR(VLOOKUP(CANTIDAD[[#This Row],[Ubicación]],SAP[],8,FALSE),"") -> 44 | G10: =IFERROR(VLOOKUP(CANTIDAD[[#This Row],[Ubicación]],SAP[],9,FALSE),"") -> CJA | H10: =IFERROR(VLOOKUP(CANTIDAD[[#This Row],[Ubicación]],SAP[],5,FALSE),"") -> 2607245060 | I10: =IFERROR(VLOOKUP(CANTIDAD[[#This Row],[Ubicación]],SAP[],6,FALSE),"") -> 24/07/2028 | J10: =IFERROR(VLOOKUP(CANTIDAD[[#This Row],[Ubicación]],SAP[],7,FALSE),"") -> 1F | K10: =IFERROR(VLOOKUP(CANTIDAD[[#This Row],[Ubicación]],SAP[],10,FALSE),"") -> 528 | L10: =IFERROR(VLOOKUP(CANTIDAD[[#This Row],[Producto]],MARA[],5,FALSE),"") -> 26 | M10: =IFERROR(VLOOKUP(CANTIDAD[[#This Row],[Producto]],MARA[],4,FALSE),"") -> CJA | N10: 99f2985a-bd91-41b2-9f53-d6e81ef26d63
A11: ="PASILLO " & VALUE(MID(B11, 4, 2)) -> PASILLO 1 | B11: AP-01-014-1 | C11: =IFERROR(VLOOKUP(CANTIDAD[[#This Row],[Ubicación]],SAP[],3,FALSE),"") -> 8325093 | D11: =IFERROR(VLOOKUP(CANTIDAD[[#This Row],[Producto]],MARA[],3,FALSE),"") -> 27751851020156 | E11: =IFERROR(VLOOKUP(CANTIDAD[[#This Row],[Ubicación]],SAP[],4,FALSE),"") -> INSEC.MATATODO SAPOLIO 2A 360ML 12UND | F11: =IFERROR(VLOOKUP(CANTIDAD[[#This Row],[Ubicación]],SAP[],8,FALSE),"") -> 19 | G11: =IFERROR(VLOOKUP(CANTIDAD[[#This Row],[Ubicación]],SAP[],9,FALSE),"") -> CJA | H11: =IFERROR(VLOOKUP(CANTIDAD[[#This Row],[Ubicación]],SAP[],5,FALSE),"") -> 2608125060 | I11: =IFERROR(VLOOKUP(CANTIDAD[[#This Row],[Ubicación]],SAP[],6,FALSE),"") -> 47095 | J11: =IFERROR(VLOOKUP(CANTIDAD[[#This Row],[Ubicación]],SAP[],7,FALSE),"") -> 1F | K11: =IFERROR(VLOOKUP(CANTIDAD[[#This Row],[Ubicación]],SAP[],10,FALSE),"") -> 228 | L11: =IFERROR(VLOOKUP(CANTIDAD[[#This Row],[Producto]],MARA[],5,FALSE),"") -> 26 | M11: =IFERROR(VLOOKUP(CANTIDAD[[#This Row],[Producto]],MARA[],4,FALSE),"") -> CJA | N11: a24b12da-2175-4335-a43b-bc36a0f420a0
A12: ="PASILLO " & VALUE(MID(B12, 4, 2)) -> PASILLO 1 | B12: AP-01-015-1 | C12: =IFERROR(VLOOKUP(CANTIDAD[[#This Row],[Ubicación]],SAP[],3,FALSE),"") | D12: =IFERROR(VLOOKUP(CANTIDAD[[#This Row],[Producto]],MARA[],3,FALSE),"") | E12: =IFERROR(VLOOKUP(CANTIDAD[[#This Row],[Ubicación]],SAP[],4,FALSE),"") | F12: =IFERROR(VLOOKUP(CANTIDAD[[#This Row],[Ubicación]],SAP[],8,FALSE),"") | G12: =IFERROR(VLOOKUP(CANTIDAD[[#This Row],[Ubicación]],SAP[],9,FALSE),"") | H12: =IFERROR(VLOOKUP(CANTIDAD[[#This Row],[Ubicación]],SAP[],5,FALSE),"") | I12: =IFERROR(VLOOKUP(CANTIDAD[[#This Row],[Ubicación]],SAP[],6,FALSE),"") | J12: =IFERROR(VLOOKUP(CANTIDAD[[#This Row],[Ubicación]],SAP[],7,FALSE),"") | K12: =IFERROR(VLOOKUP(CANTIDAD[[#This Row],[Ubicación]],SAP[],10,FALSE),"") | L12: =IFERROR(VLOOKUP(CANTIDAD[[#This Row],[Producto]],MARA[],5,FALSE),"") | M12: =IFERROR(VLOOKUP(CANTIDAD[[#This Row],[Producto]],MARA[],4,FALSE),"") | N12: 0d4755c9-4429-449f-a0e1-b88b765d999f
A13: ="PASILLO " & VALUE(MID(B13, 4, 2)) -> PASILLO 1 | B13: AP-01-016-1 | C13: =IFERROR(VLOOKUP(CANTIDAD[[#This Row],[Ubicación]],SAP[],3,FALSE),"") -> 8325084 | D13: =IFERROR(VLOOKUP(CANTIDAD[[#This Row],[Producto]],MARA[],3,FALSE),"") -> 67751851006622 | E13: =IFERROR(VLOOKUP(CANTIDAD[[#This Row],[Ubicación]],SAP[],4,FALSE),"") -> INSE. SAP. MAT MOS Y ZANC BO 360ML 12UND | F13: =IFERROR(VLOOKUP(CANTIDAD[[#This Row],[Ubicación]],SAP[],8,FALSE),"") -> 60 | G13: =IFERROR(VLOOKUP(CANTIDAD[[#This Row],[Ubicación]],SAP[],9,FALSE),"") -> CJA | H13: =IFERROR(VLOOKUP(CANTIDAD[[#This Row],[Ubicación]],SAP[],5,FALSE),"") -> 2608245060 | I13: =IFERROR(VLOOKUP(CANTIDAD[[#This Row],[Ubicación]],SAP[],6,FALSE),"") -> 24/08/2028 | J13: =IFERROR(VLOOKUP(CANTIDAD[[#This Row],[Ubicación]],SAP[],7,FALSE),"") -> 1F | K13: =IFERROR(VLOOKUP(CANTIDAD[[#This Row],[Ubicación]],SAP[],10,FALSE),"") -> 720 | L13: =IFERROR(VLOOKUP(CANTIDAD[[#This Row],[Producto]],MARA[],5,FALSE),"") -> 26 | M13: =IFERROR(VLOOKUP(CANTIDAD[[#This Row],[Producto]],MARA[],4,FALSE),"") -> CJA | N13: 8f336a74-22ba-46ed-8de8-f35e61e7d517
... A601: ="PASILLO " & VALUE(MID(B601, 4, 2)) -> PASILLO 16 | B601: PP-16-052-1 | C601: =IFERROR(VLOOKUP(CANTIDAD[[#This Row],[Ubicación]],SAP[],3,FALSE),"") | D601: =IFERROR(VLOOKUP(CANTIDAD[[#This Row],[Producto]],MARA[],3,FALSE),"") | E601: =IFERROR(VLOOKUP(CANTIDAD[[#This Row],[Ubicación]],SAP[],4,FALSE),"") | F601: =IFERROR(VLOOKUP(CANTIDAD[[#This Row],[Ubicación]],SAP[],8,FALSE),"") | G601: =IFERROR(VLOOKUP(CANTIDAD[[#This Row],[Ubicación]],SAP[],9,FALSE),"") | H601: =IFERROR(VLOOKUP(CANTIDAD[[#This Row],[Ubicación]],SAP[],5,FALSE),"") | I601: =IFERROR(VLOOKUP(CANTIDAD[[#This Row],[Ubicación]],SAP[],6,FALSE),"") | J601: =IFERROR(VLOOKUP(CANTIDAD[[#This Row],[Ubicación]],SAP[],7,FALSE),"") | K601: =IFERROR(VLOOKUP(CANTIDAD[[#This Row],[Ubicación]],SAP[],10,FALSE),"") | L601: =IFERROR(VLOOKUP(CANTIDAD[[#This Row],[Producto]],MARA[],5,FALSE),"") | M601: =IFERROR(VLOOKUP(CANTIDAD[[#This Row],[Producto]],MARA[],4,FALSE),"") | N601: 5568628d-4aa1-4aa8-a75e-21420380742a

Sheet OPERARIOS
A1: NOMBRE | B1: __PowerAppsId__
A2: RUTH | B2: e4194c23-ddd4-4eb1-b4a1-b9461f030591
A3: MARCO | B3: 254aa4c5-88b2-4813-9a06-4a16f37819dc
A4: LUIS | B4: c40951da-15a6-417f-9e2c-3604e50754d8
A5: DOÑES | B5: d4337582-fd70-4db0-88a0-45d81f35fc21
A6: SCOOBY | B6: 64ba0427-8251-4ae1-bece-9fc4c6a830ae
A7: carlos | B7: a9fc3486-e27b-4efe-8b26-d4919ac43f89

Sheet Tiempos
A1: Pasillo | B1: Estado | C1: Operario | D1: Avance | E1: Ub. Registradas | F1: Total de Ubicaciones | G1: Inicio | H1: Fin | I1: DuracionMin | J1: DIFERENCIAS | K1: STATUS | L1: DIFERENCIAS2 | M1: STATUS RECONTEO | N1: __PowerAppsId__
A2: Pasillo 1 | B2: En Proceso | C2: RUTH | D2: =IFERROR(Tiempos[[#This Row],[Ub. Registradas]]/Tiempos[[#This Row],[Total de Ubicaciones]],"") -> 0.05 | E2: {=IFERROR(ROWS(_xlfn.UNIQUE(_xlfn._xlws.FILTER('Registros'!D:D, ('Registros'!C:C=Tiempos[[#This Row],[Pasillo]]) * ('Registros'!E:E<>"")))), 0)} -> 2 | F2: =COUNTIF('CRUCE'!A:A, Tiempos[[#This Row],[Pasillo]]) -> 40 | G2: 46293.749 | I2: =IF(OR(Tiempos[[#This Row],[Inicio]]="", Tiempos[[#This Row],[Fin]]=""), "", (Tiempos[[#This Row],[Fin]]-Tiempos[[#This Row],[Inicio]])*1440) | J2: =COUNTIFS(CRUCE[PASILLO], Tiempos[[#This Row],[Pasillo]], CRUCE[STATUS], "<>CUADRADO",CRUCE[STATUS], "<>PENDIENTE") -> 0 | K2: =IF(Tiempos[[#This Row],[Estado]]="PENDIENTE", "", IF(Tiempos[[#This Row],[DIFERENCIAS]]=0, "Cuadrado", "Reconteo")) -> Cuadrado | L2: =COUNTIFS(CRUCE[PASILLO], Tiempos[[#This Row],[Pasillo]], CRUCE[STATUS2], "<>CUADRADO",CRUCE[STATUS2], "<>PENDIENTE") -> 0 | M2: =IF(Tiempos[[#This Row],[STATUS]]="cuadrado", "", IF(Tiempos[[#This Row],[DIFERENCIAS2]]=0, "Cuadrado", "Reconteo")) | N2: 1f1ee163-8703-45b8-a9ad-78909e947f5e
A3: Pasillo 5 | B3: Pendiente | D3: =IFERROR(Tiempos[[#This Row],[Ub. Registradas]]/Tiempos[[#This Row],[Total de Ubicaciones]],"") -> 0 | E3: {=IFERROR(ROWS(_xlfn.UNIQUE(_xlfn._xlws.FILTER('Registros'!D:D, ('Registros'!C:C=Tiempos[[#This Row],[Pasillo]]) * ('Registros'!E:E<>"")))), 0)} -> 0 | F3: =COUNTIF('CRUCE'!A:A, Tiempos[[#This Row],[Pasillo]]) -> 48 | I3: =IF(OR(Tiempos[[#This Row],[Inicio]]="", Tiempos[[#This Row],[Fin]]=""), "", (Tiempos[[#This Row],[Fin]]-Tiempos[[#This Row],[Inicio]])*1440) | J3: =COUNTIFS(CRUCE[PASILLO], Tiempos[[#This Row],[Pasillo]], CRUCE[STATUS], "<>CUADRADO",CRUCE[STATUS], "<>PENDIENTE") -> 0 | K3: =IF(Tiempos[[#This Row],[Estado]]="PENDIENTE", "", IF(Tiempos[[#This Row],[DIFERENCIAS]]=0, "Cuadrado", "Reconteo")) | L3: =COUNTIFS(CRUCE[PASILLO], Tiempos[[#This Row],[Pasillo]], CRUCE[STATUS2], "<>CUADRADO",CRUCE[STATUS2], "<>PENDIENTE") -> 0 | M3: =IF(Tiempos[[#This Row],[STATUS]]="cuadrado", "", IF(Tiempos[[#This Row],[DIFERENCIAS2]]=0, "Cuadrado", "Reconteo")) -> Cuadrado | N3: 194d4492-109e-45a6-bf45-6caf709d5b34
A4: Pasillo 6 | B4: Pendiente | D4: =IFERROR(Tiempos[[#This Row],[Ub. Registradas]]/Tiempos[[#This Row],[Total de Ubicaciones]],"") -> 0 | E4: {=IFERROR(ROWS(_xlfn.UNIQUE(_xlfn._xlws.FILTER('Registros'!D:D, ('Registros'!C:C=Tiempos[[#This Row],[Pasillo]]) * ('Registros'!E:E<>"")))), 0)} -> 0 | F4: =COUNTIF('CRUCE'!A:A, Tiempos[[#This Row],[Pasillo]]) -> 51 | I4: =IF(OR(Tiempos[[#This Row],[Inicio]]="", Tiempos[[#This Row],[Fin]]=""), "", (Tiempos[[#This Row],[Fin]]-Tiempos[[#This Row],[Inicio]])*1440) | J4: =COUNTIFS(CRUCE[PASILLO], Tiempos[[#This Row],[Pasillo]], CRUCE[STATUS], "<>CUADRADO",CRUCE[STATUS], "<>PENDIENTE") -> 0 | K4: =IF(Tiempos[[#This Row],[Estado]]="PENDIENTE", "", IF(Tiempos[[#This Row],[DIFERENCIAS]]=0, "Cuadrado", "Reconteo")) | L4: =COUNTIFS(CRUCE[PASILLO], Tiempos[[#This Row],[Pasillo]], CRUCE[STATUS2], "<>CUADRADO",CRUCE[STATUS2], "<>PENDIENTE") -> 0 | M4: =IF(Tiempos[[#This Row],[STATUS]]="cuadrado", "", IF(Tiempos[[#This Row],[DIFERENCIAS2]]=0, "Cuadrado", "Reconteo")) -> Cuadrado | N4: 76c65302-dbca-4bc5-ad98-ec0a172c413f
A5: Pasillo 7 | B5: Pendiente | D5: =IFERROR(Tiempos[[#This Row],[Ub. Registradas]]/Tiempos[[#This Row],[Total de Ubicaciones]],"") -> 0 | E5: {=IFERROR(ROWS(_xlfn.UNIQUE(_xlfn._xlws.FILTER('Registros'!D:D, ('Registros'!C:C=Tiempos[[#This Row],[Pasillo]]) * ('Registros'!E:E<>"")))), 0)} -> 0 | F5: =COUNTIF('CRUCE'!A:A, Tiempos[[#This Row],[Pasillo]]) -> 51 | I5: =IF(OR(Tiempos[[#This Row],[Inicio]]="", Tiempos[[#This Row],[Fin]]=""), "", (Tiempos[[#This Row],[Fin]]-Tiempos[[#This Row],[Inicio]])*1440) | J5: =COUNTIFS(CRUCE[PASILLO], Tiempos[[#This Row],[Pasillo]], CRUCE[STATUS], "<>CUADRADO",CRUCE[STATUS], "<>PENDIENTE") -> 0 | K5: =IF(Tiempos[[#This Row],[Estado]]="PENDIENTE", "", IF(Tiempos[[#This Row],[DIFERENCIAS]]=0, "Cuadrado", "Reconteo")) | L5: =COUNTIFS(CRUCE[PASILLO], Tiempos[[#This Row],[Pasillo]], CRUCE[STATUS2], "<>CUADRADO",CRUCE[STATUS2], "<>PENDIENTE") -> 0 | M5: =IF(Tiempos[[#This Row],[STATUS]]="cuadrado", "", IF(Tiempos[[#This Row],[DIFERENCIAS2]]=0, "Cuadrado", "Reconteo")) -> Cuadrado | N5: fdbe60f2-c6db-4617-ae2f-6f07885345d0
A6: Pasillo 8 | B6: Pendiente | D6: =IFERROR(Tiempos[[#This Row],[Ub. Registradas]]/Tiempos[[#This Row],[Total de Ubicaciones]],"") -> 0 | E6: {=IFERROR(ROWS(_xlfn.UNIQUE(_xlfn._xlws.FILTER('Registros'!D:D, ('Registros'!C:C=Tiempos[[#This Row],[Pasillo]]) * ('Registros'!E:E<>"")))), 0)} -> 0 | F6: =COUNTIF('CRUCE'!A:A, Tiempos[[#This Row],[Pasillo]]) -> 52 | I6: =IF(OR(Tiempos[[#This Row],[Inicio]]="", Tiempos[[#This Row],[Fin]]=""), "", (Tiempos[[#This Row],[Fin]]-Tiempos[[#This Row],[Inicio]])*1440) | J6: =COUNTIFS(CRUCE[PASILLO], Tiempos[[#This Row],[Pasillo]], CRUCE[STATUS], "<>CUADRADO",CRUCE[STATUS], "<>PENDIENTE") -> 0 | K6: =IF(Tiempos[[#This Row],[Estado]]="PENDIENTE", "", IF(Tiempos[[#This Row],[DIFERENCIAS]]=0, "Cuadrado", "Reconteo")) | L6: =COUNTIFS(CRUCE[PASILLO], Tiempos[[#This Row],[Pasillo]], CRUCE[STATUS2], "<>CUADRADO",CRUCE[STATUS2], "<>PENDIENTE") -> 1 | M6: =IF(Tiempos[[#This Row],[STATUS]]="cuadrado", "", IF(Tiempos[[#This Row],[DIFERENCIAS2]]=0, "Cuadrado", "Reconteo")) -> Reconteo | N6: f507ee28-44dd-46fa-8952-12d603c9893f
A7: Pasillo 9 | B7: Pendiente | D7: =IFERROR(Tiempos[[#This Row],[Ub. Registradas]]/Tiempos[[#This Row],[Total de Ubicaciones]],"") -> 0 | E7: {=IFERROR(ROWS(_xlfn.UNIQUE(_xlfn._xlws.FILTER('Registros'!D:D, ('Registros'!C:C=Tiempos[[#This Row],[Pasillo]]) * ('Registros'!E:E<>"")))), 0)} -> 0 | F7: =COUNTIF('CRUCE'!A:A, Tiempos[[#This Row],[Pasillo]]) -> 51 | I7: =IF(OR(Tiempos[[#This Row],[Inicio]]="", Tiempos[[#This Row],[Fin]]=""), "", (Tiempos[[#This Row],[Fin]]-Tiempos[[#This Row],[Inicio]])*1440) | J7: =COUNTIFS(CRUCE[PASILLO], Tiempos[[#This Row],[Pasillo]], CRUCE[STATUS], "<>CUADRADO",CRUCE[STATUS], "<>PENDIENTE") -> 0 | K7: =IF(Tiempos[[#This Row],[Estado]]="PENDIENTE", "", IF(Tiempos[[#This Row],[DIFERENCIAS]]=0, "Cuadrado", "Reconteo")) | L7: =COUNTIFS(CRUCE[PASILLO], Tiempos[[#This Row],[Pasillo]], CRUCE[STATUS2], "<>CUADRADO",CRUCE[STATUS2], "<>PENDIENTE") -> 0 | M7: =IF(Tiempos[[#This Row],[STATUS]]="cuadrado", "", IF(Tiempos[[#This Row],[DIFERENCIAS2]]=0, "Cuadrado", "Reconteo")) -> Cuadrado | N7: 8ee267b8-1051-42c9-a3ca-eeda55364e76
A8: Pasillo 10 | B8: Pendiente | D8: =IFERROR(Tiempos[[#This Row],[Ub. Registradas]]/Tiempos[[#This Row],[Total de Ubicaciones]],"") -> 0 | E8: {=IFERROR(ROWS(_xlfn.UNIQUE(_xlfn._xlws.FILTER('Registros'!D:D, ('Registros'!C:C=Tiempos[[#This Row],[Pasillo]]) * ('Registros'!E:E<>"")))), 0)} -> 0 | F8: =COUNTIF('CRUCE'!A:A, Tiempos[[#This Row],[Pasillo]]) -> 51 | I8: =IF(OR(Tiempos[[#This Row],[Inicio]]="", Tiempos[[#This Row],[Fin]]=""), "", (Tiempos[[#This Row],[Fin]]-Tiempos[[#This Row],[Inicio]])*1440) | J8: =COUNTIFS(CRUCE[PASILLO], Tiempos[[#This Row],[Pasillo]], CRUCE[STATUS], "<>CUADRADO",CRUCE[STATUS], "<>PENDIENTE") -> 0 | K8: =IF(Tiempos[[#This Row],[Estado]]="PENDIENTE", "", IF(Tiempos[[#This Row],[DIFERENCIAS]]=0, "Cuadrado", "Reconteo")) | L8: =COUNTIFS(CRUCE[PASILLO], Tiempos[[#This Row],[Pasillo]], CRUCE[STATUS2], "<>CUADRADO",CRUCE[STATUS2], "<>PENDIENTE") -> 0 | M8: =IF(Tiempos[[#This Row],[STATUS]]="cuadrado", "", IF(Tiempos[[#This Row],[DIFERENCIAS2]]=0, "Cuadrado", "Reconteo")) -> Cuadrado | N8: cdd9f442-c8d2-4380-ab8e-f4bf33c7d872
A9: Pasillo 11 | B9: Pendiente | D9: =IFERROR(Tiempos[[#This Row],[Ub. Registradas]]/Tiempos[[#This Row],[Total de Ubicaciones]],"") -> 0 | E9: {=IFERROR(ROWS(_xlfn.UNIQUE(_xlfn._xlws.FILTER('Registros'!D:D, ('Registros'!C:C=Tiempos[[#This Row],[Pasillo]]) * ('Registros'!E:E<>"")))), 0)} -> 0 | F9: =COUNTIF('CRUCE'!A:A, Tiempos[[#This Row],[Pasillo]]) -> 52 | I9: =IF(OR(Tiempos[[#This Row],[Inicio]]="", Tiempos[[#This Row],[Fin]]=""), "", (Tiempos[[#This Row],[Fin]]-Tiempos[[#This Row],[Inicio]])*1440) | J9: =COUNTIFS(CRUCE[PASILLO], Tiempos[[#This Row],[Pasillo]], CRUCE[STATUS], "<>CUADRADO",CRUCE[STATUS], "<>PENDIENTE") -> 0 | K9: =IF(Tiempos[[#This Row],[Estado]]="PENDIENTE", "", IF(Tiempos[[#This Row],[DIFERENCIAS]]=0, "Cuadrado", "Reconteo")) | L9: =COUNTIFS(CRUCE[PASILLO], Tiempos[[#This Row],[Pasillo]], CRUCE[STATUS2], "<>CUADRADO",CRUCE[STATUS2], "<>PENDIENTE") -> 0 | M9: =IF(Tiempos[[#This Row],[STATUS]]="cuadrado", "", IF(Tiempos[[#This Row],[DIFERENCIAS2]]=0, "Cuadrado", "Reconteo")) -> Cuadrado | N9: eb7c406e-0b40-4cac-9f90-c8e6604df8f4
A10: Pasillo 12 | B10: Pendiente | D10: =IFERROR(Tiempos[[#This Row],[Ub. Registradas]]/Tiempos[[#This Row],[Total de Ubicaciones]],"") -> 0 | E10: {=IFERROR(ROWS(_xlfn.UNIQUE(_xlfn._xlws.FILTER('Registros'!D:D, ('Registros'!C:C=Tiempos[[#This Row],[Pasillo]]) * ('Registros'!E:E<>"")))), 0)} -> 0 | F10: =COUNTIF('CRUCE'!A:A, Tiempos[[#This Row],[Pasillo]]) -> 51 | I10: =IF(OR(Tiempos[[#This Row],[Inicio]]="", Tiempos[[#This Row],[Fin]]=""), "", (Tiempos[[#This Row],[Fin]]-Tiempos[[#This Row],[Inicio]])*1440) | J10: =COUNTIFS(CRUCE[PASILLO], Tiempos[[#This Row],[Pasillo]], CRUCE[STATUS], "<>CUADRADO",CRUCE[STATUS], "<>PENDIENTE") -> 0 | K10: =IF(Tiempos[[#This Row],[Estado]]="PENDIENTE", "", IF(Tiempos[[#This Row],[DIFERENCIAS]]=0, "Cuadrado", "Reconteo")) | L10: =COUNTIFS(CRUCE[PASILLO], Tiempos[[#This Row],[Pasillo]], CRUCE[STATUS2], "<>CUADRADO",CRUCE[STATUS2], "<>PENDIENTE") -> 0 | M10: =IF(Tiempos[[#This Row],[STATUS]]="cuadrado", "", IF(Tiempos[[#This Row],[DIFERENCIAS2]]=0, "Cuadrado", "Reconteo")) -> Cuadrado | N10: d4ed75ff-4c90-493f-81d8-db9925e32d24
A11: Pasillo 13 | B11: Pendiente | D11: =IFERROR(Tiempos[[#This Row],[Ub. Registradas]]/Tiempos[[#This Row],[Total de Ubicaciones]],"") -> 0 | E11: {=IFERROR(ROWS(_xlfn.UNIQUE(_xlfn._xlws.FILTER('Registros'!D:D, ('Registros'!C:C=Tiempos[[#This Row],[Pasillo]]) * ('Registros'!E:E<>"")))), 0)} -> 0 | F11: =COUNTIF('CRUCE'!A:A, Tiempos[[#This Row],[Pasillo]]) -> 51 | I11: =IF(OR(Tiempos[[#This Row],[Inicio]]="", Tiempos[[#This Row],[Fin]]=""), "", (Tiempos[[#This Row],[Fin]]-Tiempos[[#This Row],[Inicio]])*1440) | J11: =COUNTIFS(CRUCE[PASILLO], Tiempos[[#This Row],[Pasillo]], CRUCE[STATUS], "<>CUADRADO",CRUCE[STATUS], "<>PENDIENTE") -> 0 | K11: =IF(Tiempos[[#This Row],[Estado]]="PENDIENTE", "", IF(Tiempos[[#This Row],[DIFERENCIAS]]=0, "Cuadrado", "Reconteo")) | L11: =COUNTIFS(CRUCE[PASILLO], Tiempos[[#This Row],[Pasillo]], CRUCE[STATUS2], "<>CUADRADO",CRUCE[STATUS2], "<>PENDIENTE") -> 0 | M11: =IF(Tiempos[[#This Row],[STATUS]]="cuadrado", "", IF(Tiempos[[#This Row],[DIFERENCIAS2]]=0, "Cuadrado", "Reconteo")) -> Cuadrado | N11: 544cb243-e28b-4a62-b8dd-6cb17df0813a
A12: Pasillo 15 | B12: Pendiente | D12: =IFERROR(Tiempos[[#This Row],[Ub. Registradas]]/Tiempos[[#This Row],[Total de Ubicaciones]],"") -> 0 | E12: {=IFERROR(ROWS(_xlfn.UNIQUE(_xlfn._xlws.FILTER('Registros'!D:D, ('Registros'!C:C=Tiempos[[#This Row],[Pasillo]]) * ('Registros'!E:E<>"")))), 0)} -> 0 | F12: =COUNTIF('CRUCE'!A:A, Tiempos[[#This Row],[Pasillo]]) -> 51 | I12: =IF(OR(Tiempos[[#This Row],[Inicio]]="", Tiempos[[#This Row],[Fin]]=""), "", (Tiempos[[#This Row],[Fin]]-Tiempos[[#This Row],[Inicio]])*1440) | J12: =COUNTIFS(CRUCE[PASILLO], Tiempos[[#This Row],[Pasillo]], CRUCE[STATUS], "<>CUADRADO",CRUCE[STATUS], "<>PENDIENTE") -> 0 | K12: =IF(Tiempos[[#This Row],[Estado]]="PENDIENTE", "", IF(Tiempos[[#This Row],[DIFERENCIAS]]=0, "Cuadrado", "Reconteo")) | L12: =COUNTIFS(CRUCE[PASILLO], Tiempos[[#This Row],[Pasillo]], CRUCE[STATUS2], "<>CUADRADO",CRUCE[STATUS2], "<>PENDIENTE") -> 0 | M12: =IF(Tiempos[[#This Row],[STATUS]]="cuadrado", "", IF(Tiempos[[#This Row],[DIFERENCIAS2]]=0, "Cuadrado", "Reconteo")) -> Cuadrado | N12: 22c1e7b9-c56a-40cb-8750-4fe62f376eab
A13: Pasillo 16 | B13: Pendiente | D13: =IFERROR(Tiempos[[#This Row],[Ub. Registradas]]/Tiempos[[#This Row],[Total de Ubicaciones]],"") -> 0 | E13: {=IFERROR(ROWS(_xlfn.UNIQUE(_xlfn._xlws.FILTER('Registros'!D:D, ('Registros'!C:C=Tiempos[[#This Row],[Pasillo]]) * ('Registros'!E:E<>"")))), 0)} -> 0 | F13: =COUNTIF('CRUCE'!A:A, Tiempos[[#This Row],[Pasillo]]) -> 51 | I13: =IF(OR(Tiempos[[#This Row],[Inicio]]="", Tiempos[[#This Row],[Fin]]=""), "", (Tiempos[[#This Row],[Fin]]-Tiempos[[#This Row],[Inicio]])*1440) | J13: =COUNTIFS(CRUCE[PASILLO], Tiempos[[#This Row],[Pasillo]], CRUCE[STATUS], "<>CUADRADO",CRUCE[STATUS], "<>PENDIENTE") -> 0 | K13: =IF(Tiempos[[#This Row],[Estado]]="PENDIENTE", "", IF(Tiempos[[#This Row],[DIFERENCIAS]]=0, "Cuadrado", "Reconteo")) | L13: =COUNTIFS(CRUCE[PASILLO], Tiempos[[#This Row],[Pasillo]], CRUCE[STATUS2], "<>CUADRADO",CRUCE[STATUS2], "<>PENDIENTE") -> 0 | M13: =IF(Tiempos[[#This Row],[STATUS]]="cuadrado", "", IF(Tiempos[[#This Row],[DIFERENCIAS2]]=0, "Cuadrado", "Reconteo")) -> Cuadrado | N13: aa9dda26-5515-41b2-b63c-d291ba000810
A14: Pasillo 23 | B14: Pendiente | D14: =IFERROR(Tiempos[[#This Row],[Ub. Registradas]]/Tiempos[[#This Row],[Total de Ubicaciones]],"") | E14: {=IFERROR(ROWS(_xlfn.UNIQUE(_xlfn._xlws.FILTER('Registros'!D:D, ('Registros'!C:C=Tiempos[[#This Row],[Pasillo]]) * ('Registros'!E:E<>"")))), 0)} -> 0 | F14: =COUNTIF('CRUCE'!A:A, Tiempos[[#This Row],[Pasillo]]) -> 0 | I14: =IF(OR(Tiempos[[#This Row],[Inicio]]="", Tiempos[[#This Row],[Fin]]=""), "", (Tiempos[[#This Row],[Fin]]-Tiempos[[#This Row],[Inicio]])*1440) | J14: =COUNTIFS(CRUCE[PASILLO], Tiempos[[#This Row],[Pasillo]], CRUCE[STATUS], "<>CUADRADO",CRUCE[STATUS], "<>PENDIENTE") -> 0 | K14: =IF(Tiempos[[#This Row],[Estado]]="PENDIENTE", "", IF(Tiempos[[#This Row],[DIFERENCIAS]]=0, "Cuadrado", "Reconteo")) | L14: =COUNTIFS(CRUCE[PASILLO], Tiempos[[#This Row],[Pasillo]], CRUCE[STATUS2], "<>CUADRADO",CRUCE[STATUS2], "<>PENDIENTE") -> 0 | M14: =IF(Tiempos[[#This Row],[STATUS]]="cuadrado", "", IF(Tiempos[[#This Row],[DIFERENCIAS2]]=0, "Cuadrado", "Reconteo")) -> Cuadrado | N14: ecb5d4f6-08b3-43e8-8963-012deccc276b

Sheet Registros
A1: Fecha | B1: Operario | C1: Pasillo | D1: Ubicacion | E1: Codigo | F1: Descripcion | G1: UMA | H1: CamaPqt | I1: Niveles | J1: Saldo | K1: Total
A2: 28 septiembre 2026 13:00 | B2: RUTH | C2: Pasillo 1 | D2: PP-007-001-1 | E2: VACÍO | F2: UBICACIÓN VACÍA | G2: - | H2: 0 | I2: 0 | J2: 0 | K2: 0 | M2: NO DEBE DEJAR GUARDAR CUANDO ESORRO PASILLO
A3: 28 septiembre 2026 13:03 | B3: RUTH | C3: Pasillo 1 | D3: AP-01-005-1 | E3: 8325056 | F3: INSEC.CASA&JARDIN SAPOLIO 2A 360ML 12UND | G3: CJA | H3: 26 | I3: 0 | J3: 5 | K3: 5

Sheet CRUCE
H1: CONTEO 1 | N1: CONTEO 2
A2: PASILLO | B2: Ubicacion | C2: SKU | D2: EAN | E2: DESCRIPCION | F2: BULTOS | G2: UMA | H2: CODIGO | I2: TOTAL | J2: UMA2 | K2: Diferencia | L2: STATUS | M2: RECONTEO | N2: CODIGO2 | O2: TOTAL2 | P2: DIFERENCIA2 | Q2: STATUS2 | R2: C | S2: __PowerAppsId__
A3: PASILLO 1 | B3: AP-01-005-1 | C3: 8325056 | D3: 37751851006645 | E3: INSEC.CASA&JARDIN SAPOLIO 2A 360ML 12UND | F3: 5 | G3: CJA | H3: =_xlfn.XLOOKUP(CRUCE[[#This Row],[Ubicacion]],Registros[Ubicacion],Registros[Codigo], "") -> 8325056 | I3: =_xlfn.XLOOKUP(CRUCE[[#This Row],[Ubicacion]],Registros[Ubicacion],Registros[Total], "") -> 5 | J3: =_xlfn.XLOOKUP(CRUCE[[#This Row],[Ubicacion]],Registros[Ubicacion],Registros[UMA], "") -> CJA | K3: =IF(CRUCE[[#This Row],[TOTAL]]="","",CRUCE[[#This Row],[TOTAL]]-CRUCE[[#This Row],[BULTOS]]) -> 0 | L3: =IF(CRUCE[[#This Row],[TOTAL]]="", "PENDIENTE", IF(CRUCE[[#This Row],[Diferencia]]=0, "CUADRADO", IF(CRUCE[[#This Row],[Diferencia]]>0, "SOBRANTE", "FALTANTE"))) -> CUADRADO | M3: =IF(CRUCE[[#This Row],[Diferencia]]="","",IF(CRUCE[[#This Row],[Diferencia]]=0,"OK","RECONTEO")) -> OK | N3: =_xlfn.XLOOKUP(CRUCE[[#This Row],[Ubicacion]],Registros[Ubicacion],Registros[Codigo], "") -> 8325056 | Q3: =IF(CRUCE[[#This Row],[TOTAL2]]="", "PENDIENTE", IF(CRUCE[[#This Row],[DIFERENCIA2]]=0, "CUADRADO", IF(CRUCE[[#This Row],[DIFERENCIA2]]>0, "SOBRANTE", "FALTANTE"))) -> PENDIENTE | S3: e56a3784-2ab1-4e9f-9639-646dacf26db3
A4: PASILLO 1 | B4: AP-01-006-1 | C4: 8325096 | D4: 37751851006652 | E4: INSEC.MATAPOLILLAS SAPOLIO 2A 360ML 12UN | F4: 9 | G4: CJA | H4: =_xlfn.XLOOKUP(CRUCE[[#This Row],[Ubicacion]],Registros[Ubicacion],Registros[Codigo], "") | I4: =_xlfn.XLOOKUP(CRUCE[[#This Row],[Ubicacion]],Registros[Ubicacion],Registros[Total], "") | J4: =_xlfn.XLOOKUP(CRUCE[[#This Row],[Ubicacion]],Registros[Ubicacion],Registros[UMA], "") | K4: =IF(CRUCE[[#This Row],[TOTAL]]="","",CRUCE[[#This Row],[TOTAL]]-CRUCE[[#This Row],[BULTOS]]) | L4: =IF(CRUCE[[#This Row],[TOTAL]]="", "PENDIENTE", IF(CRUCE[[#This Row],[Diferencia]]=0, "CUADRADO", IF(CRUCE[[#This Row],[Diferencia]]>0, "SOBRANTE", "FALTANTE"))) -> PENDIENTE | M4: =IF(CRUCE[[#This Row],[Diferencia]]="","",IF(CRUCE[[#This Row],[Diferencia]]=0,"OK","RECONTEO")) | N4: =_xlfn.XLOOKUP(CRUCE[[#This Row],[Ubicacion]],Registros[Ubicacion],Registros[Codigo], "") | Q4: =IF(CRUCE[[#This Row],[TOTAL2]]="", "PENDIENTE", IF(CRUCE[[#This Row],[DIFERENCIA2]]=0, "CUADRADO", IF(CRUCE[[#This Row],[DIFERENCIA2]]>0, "SOBRANTE", "FALTANTE"))) -> PENDIENTE | R4: --- | S4: 86523e1f-34b1-46c1-8076-e7a5bc59b858
A5: PASILLO 1 | B5: AP-01-007-1 | C5: 8315030 | D5: 27751851006129 | E5: LIMPIAHORNOS SAPOLIO 360ML 12UND | F5: 39 | G5: CJA | H5: =_xlfn.XLOOKUP(CRUCE[[#This Row],[Ubicacion]],Registros[Ubicacion],Registros[Codigo], "") | I5: =_xlfn.XLOOKUP(CRUCE[[#This Row],[Ubicacion]],Registros[Ubicacion],Registros[Total], "") | J5: =_xlfn.XLOOKUP(CRUCE[[#This Row],[Ubicacion]],Registros[Ubicacion],Registros[UMA], "") | K5: =IF(CRUCE[[#This Row],[TOTAL]]="","",CRUCE[[#This Row],[TOTAL]]-CRUCE[[#This Row],[BULTOS]]) | L5: =IF(CRUCE[[#This Row],[TOTAL]]="", "PENDIENTE", IF(CRUCE[[#This Row],[Diferencia]]=0, "CUADRADO", IF(CRUCE[[#This Row],[Diferencia]]>0, "SOBRANTE", "FALTANTE"))) -> PENDIENTE | M5: =IF(CRUCE[[#This Row],[Diferencia]]="","",IF(CRUCE[[#This Row],[Diferencia]]=0,"OK","RECONTEO")) | N5: =_xlfn.XLOOKUP(CRUCE[[#This Row],[Ubicacion]],Registros[Ubicacion],Registros[Codigo], "") | Q5: =IF(CRUCE[[#This Row],[TOTAL2]]="", "PENDIENTE", IF(CRUCE[[#This Row],[DIFERENCIA2]]=0, "CUADRADO", IF(CRUCE[[#This Row],[DIFERENCIA2]]>0, "SOBRANTE", "FALTANTE"))) -> PENDIENTE | R5: --- | S5: 7e7c8b47-a04c-442e-b2a8-e805b786effc
A6: PASILLO 1 | B6: AP-01-008-1 | C6: 8315000 | D6: 17751851007556 | E6: LUSTRAMUEBLE LAVANDA PREMIO 360ML 12UND | F6: 15 | G6: CJA | H6: =_xlfn.XLOOKUP(CRUCE[[#This Row],[Ubicacion]],Registros[Ubicacion],Registros[Codigo], "") | I6: =_xlfn.XLOOKUP(CRUCE[[#This Row],[Ubicacion]],Registros[Ubicacion],Registros[Total], "") | J6: =_xlfn.XLOOKUP(CRUCE[[#This Row],[Ubicacion]],Registros[Ubicacion],Registros[UMA], "") | K6: =IF(CRUCE[[#This Row],[TOTAL]]="","",CRUCE[[#This Row],[TOTAL]]-CRUCE[[#This Row],[BULTOS]]) | L6: =IF(CRUCE[[#This Row],[TOTAL]]="", "PENDIENTE", IF(CRUCE[[#This Row],[Diferencia]]=0, "CUADRADO", IF(CRUCE[[#This Row],[Diferencia]]>0, "SOBRANTE", "FALTANTE"))) -> PENDIENTE | M6: =IF(CRUCE[[#This Row],[Diferencia]]="","",IF(CRUCE[[#This Row],[Diferencia]]=0,"OK","RECONTEO")) | N6: =_xlfn.XLOOKUP(CRUCE[[#This Row],[Ubicacion]],Registros[Ubicacion],Registros[Codigo], "") | Q6: =IF(CRUCE[[#This Row],[TOTAL2]]="", "PENDIENTE", IF(CRUCE[[#This Row],[DIFERENCIA2]]=0, "CUADRADO", IF(CRUCE[[#This Row],[DIFERENCIA2]]>0, "SOBRANTE", "FALTANTE"))) -> PENDIENTE | R6: --- | S6: a48087b5-f38f-420b-a0b4-24fb19d277bf
A7: PASILLO 1 | B7: AP-01-009-1 | C7: 8315001 | D7: 17751851007563 | E7: LUSTRAMUEBLE LIMON PREMIO 360ML 12UND | F7: 57 | G7: CJA | H7: =_xlfn.XLOOKUP(CRUCE[[#This Row],[Ubicacion]],Registros[Ubicacion],Registros[Codigo], "") | I7: =_xlfn.XLOOKUP(CRUCE[[#This Row],[Ubicacion]],Registros[Ubicacion],Registros[Total], "") | J7: =_xlfn.XLOOKUP(CRUCE[[#This Row],[Ubicacion]],Registros[Ubicacion],Registros[UMA], "") | K7: =IF(CRUCE[[#This Row],[TOTAL]]="","",CRUCE[[#This Row],[TOTAL]]-CRUCE[[#This Row],[BULTOS]]) | L7: =IF(CRUCE[[#This Row],[TOTAL]]="", "PENDIENTE", IF(CRUCE[[#This Row],[Diferencia]]=0, "CUADRADO", IF(CRUCE[[#This Row],[Diferencia]]>0, "SOBRANTE", "FALTANTE"))) -> PENDIENTE | M7: =IF(CRUCE[[#This Row],[Diferencia]]="","",IF(CRUCE[[#This Row],[Diferencia]]=0,"OK","RECONTEO")) | N7: =_xlfn.XLOOKUP(CRUCE[[#This Row],[Ubicacion]],Registros[Ubicacion],Registros[Codigo], "") | Q7: =IF(CRUCE[[#This Row],[TOTAL2]]="", "PENDIENTE", IF(CRUCE[[#This Row],[DIFERENCIA2]]=0, "CUADRADO", IF(CRUCE[[#This Row],[DIFERENCIA2]]>0, "SOBRANTE", "FALTANTE"))) -> PENDIENTE | R7: --- | S7: 3c749e0a-9c53-4dfe-8f70-d6d550127d39
A8: PASILLO 1 | B8: AP-01-010-1 | C8: 8325116 | D8: 47751851011196 | E8: INSEC. MATA ACAROS SAPOLIO RE 360ML 12UN | F8: 76 | G8: CJA | H8: =_xlfn.XLOOKUP(CRUCE[[#This Row],[Ubicacion]],Registros[Ubicacion],Registros[Codigo], "") | I8: =_xlfn.XLOOKUP(CRUCE[[#This Row],[Ubicacion]],Registros[Ubicacion],Registros[Total], "") | J8: =_xlfn.XLOOKUP(CRUCE[[#This Row],[Ubicacion]],Registros[Ubicacion],Registros[UMA], "") | K8: =IF(CRUCE[[#This Row],[TOTAL]]="","",CRUCE[[#This Row],[TOTAL]]-CRUCE[[#This Row],[BULTOS]]) | L8: =IF(CRUCE[[#This Row],[TOTAL]]="", "PENDIENTE", IF(CRUCE[[#This Row],[Diferencia]]=0, "CUADRADO", IF(CRUCE[[#This Row],[Diferencia]]>0, "SOBRANTE", "FALTANTE"))) -> PENDIENTE | M8: =IF(CRUCE[[#This Row],[Diferencia]]="","",IF(CRUCE[[#This Row],[Diferencia]]=0,"OK","RECONTEO")) | N8: =_xlfn.XLOOKUP(CRUCE[[#This Row],[Ubicacion]],Registros[Ubicacion],Registros[Codigo], "") | Q8: =IF(CRUCE[[#This Row],[TOTAL2]]="", "PENDIENTE", IF(CRUCE[[#This Row],[DIFERENCIA2]]=0, "CUADRADO", IF(CRUCE[[#This Row],[DIFERENCIA2]]>0, "SOBRANTE", "FALTANTE"))) -> PENDIENTE | R8: --- | S8: d37699d5-6fdc-40d5-89df-fa6a11f8b4eb
A9: PASILLO 1 | B9: AP-01-011-1 | C9: 8325118 | D9: 47751851006666 | E9: INSEC MATA TERMITAS SAPOLIO RE 360ML12UN | F9: 76 | G9: CJA | H9: =_xlfn.XLOOKUP(CRUCE[[#This Row],[Ubicacion]],Registros[Ubicacion],Registros[Codigo], "") | I9: =_xlfn.XLOOKUP(CRUCE[[#This Row],[Ubicacion]],Registros[Ubicacion],Registros[Total], "") | J9: =_xlfn.XLOOKUP(CRUCE[[#This Row],[Ubicacion]],Registros[Ubicacion],Registros[UMA], "") | K9: =IF(CRUCE[[#This Row],[TOTAL]]="","",CRUCE[[#This Row],[TOTAL]]-CRUCE[[#This Row],[BULTOS]]) | L9: =IF(CRUCE[[#This Row],[TOTAL]]="", "PENDIENTE", IF(CRUCE[[#This Row],[Diferencia]]=0, "CUADRADO", IF(CRUCE[[#This Row],[Diferencia]]>0, "SOBRANTE", "FALTANTE"))) -> PENDIENTE | M9: =IF(CRUCE[[#This Row],[Diferencia]]="","",IF(CRUCE[[#This Row],[Diferencia]]=0,"OK","RECONTEO")) | N9: =_xlfn.XLOOKUP(CRUCE[[#This Row],[Ubicacion]],Registros[Ubicacion],Registros[Codigo], "") | Q9: =IF(CRUCE[[#This Row],[TOTAL2]]="", "PENDIENTE", IF(CRUCE[[#This Row],[DIFERENCIA2]]=0, "CUADRADO", IF(CRUCE[[#This Row],[DIFERENCIA2]]>0, "SOBRANTE", "FALTANTE"))) -> PENDIENTE | R9: --- | S9: c6b4ea8c-82c2-4613-8f9e-b110c4cc6801
A10: PASILLO 1 | B10: AP-01-012-1 | C10: 8309033 | D10: 17751851019634 | E10: PERFU.RPTO V/FRANCESA SAPOLIO 240ML 12UN | F10: 50 | G10: CJA | H10: =_xlfn.XLOOKUP(CRUCE[[#This Row],[Ubicacion]],Registros[Ubicacion],Registros[Codigo], "") | I10: =_xlfn.XLOOKUP(CRUCE[[#This Row],[Ubicacion]],Registros[Ubicacion],Registros[Total], "") | J10: =_xlfn.XLOOKUP(CRUCE[[#This Row],[Ubicacion]],Registros[Ubicacion],Registros[UMA], "") | K10: =IF(CRUCE[[#This Row],[TOTAL]]="","",CRUCE[[#This Row],[TOTAL]]-CRUCE[[#This Row],[BULTOS]]) | L10: =IF(CRUCE[[#This Row],[TOTAL]]="", "PENDIENTE", IF(CRUCE[[#This Row],[Diferencia]]=0, "CUADRADO", IF(CRUCE[[#This Row],[Diferencia]]>0, "SOBRANTE", "FALTANTE"))) -> PENDIENTE | M10: =IF(CRUCE[[#This Row],[Diferencia]]="","",IF(CRUCE[[#This Row],[Diferencia]]=0,"OK","RECONTEO")) | N10: =_xlfn.XLOOKUP(CRUCE[[#This Row],[Ubicacion]],Registros[Ubicacion],Registros[Codigo], "") | Q10: =IF(CRUCE[[#This Row],[TOTAL2]]="", "PENDIENTE", IF(CRUCE[[#This Row],[DIFERENCIA2]]=0, "CUADRADO", IF(CRUCE[[#This Row],[DIFERENCIA2]]>0, "SOBRANTE", "FALTANTE"))) -> PENDIENTE | R10: --- | S10: dd1dbcb3-e43e-4526-b8e7-94dcd1ed66aa
A11: PASILLO 1 | B11: AP-01-013-1 | C11: 8325095 | D11: 37751851006638 | E11: INSEC.MATAPULGAS SAPOLIO 2A 360ML 12UND | F11: 44 | G11: CJA | H11: =_xlfn.XLOOKUP(CRUCE[[#This Row],[Ubicacion]],Registros[Ubicacion],Registros[Codigo], "") | I11: =_xlfn.XLOOKUP(CRUCE[[#This Row],[Ubicacion]],Registros[Ubicacion],Registros[Total], "") | J11: =_xlfn.XLOOKUP(CRUCE[[#This Row],[Ubicacion]],Registros[Ubicacion],Registros[UMA], "") | K11: =IF(CRUCE[[#This Row],[TOTAL]]="","",CRUCE[[#This Row],[TOTAL]]-CRUCE[[#This Row],[BULTOS]]) | L11: =IF(CRUCE[[#This Row],[TOTAL]]="", "PENDIENTE", IF(CRUCE[[#This Row],[Diferencia]]=0, "CUADRADO", IF(CRUCE[[#This Row],[Diferencia]]>0, "SOBRANTE", "FALTANTE"))) -> PENDIENTE | M11: =IF(CRUCE[[#This Row],[Diferencia]]="","",IF(CRUCE[[#This Row],[Diferencia]]=0,"OK","RECONTEO")) | N11: =_xlfn.XLOOKUP(CRUCE[[#This Row],[Ubicacion]],Registros[Ubicacion],Registros[Codigo], "") | Q11: =IF(CRUCE[[#This Row],[TOTAL2]]="", "PENDIENTE", IF(CRUCE[[#This Row],[DIFERENCIA2]]=0, "CUADRADO", IF(CRUCE[[#This Row],[DIFERENCIA2]]>0, "SOBRANTE", "FALTANTE"))) -> PENDIENTE | R11: --- | S11: ff0849b8-9b24-4a7f-b6cf-7baa42fcecad
A12: PASILLO 1 | B12: AP-01-014-1 | C12: 8325093 | D12: 27751851020156 | E12: INSEC.MATATODO SAPOLIO 2A 360ML 12UND | F12: 19 | G12: CJA | H12: =_xlfn.XLOOKUP(CRUCE[[#This Row],[Ubicacion]],Registros[Ubicacion],Registros[Codigo], "") | I12: =_xlfn.XLOOKUP(CRUCE[[#This Row],[Ubicacion]],Registros[Ubicacion],Registros[Total], "") | J12: =_xlfn.XLOOKUP(CRUCE[[#This Row],[Ubicacion]],Registros[Ubicacion],Registros[UMA], "") | K12: =IF(CRUCE[[#This Row],[TOTAL]]="","",CRUCE[[#This Row],[TOTAL]]-CRUCE[[#This Row],[BULTOS]]) | L12: =IF(CRUCE[[#This Row],[TOTAL]]="", "PENDIENTE", IF(CRUCE[[#This Row],[Diferencia]]=0, "CUADRADO", IF(CRUCE[[#This Row],[Diferencia]]>0, "SOBRANTE", "FALTANTE"))) -> PENDIENTE | M12: =IF(CRUCE[[#This Row],[Diferencia]]="","",IF(CRUCE[[#This Row],[Diferencia]]=0,"OK","RECONTEO")) | N12: =_xlfn.XLOOKUP(CRUCE[[#This Row],[Ubicacion]],Registros[Ubicacion],Registros[Codigo], "") | Q12: =IF(CRUCE[[#This Row],[TOTAL2]]="", "PENDIENTE", IF(CRUCE[[#This Row],[DIFERENCIA2]]=0, "CUADRADO", IF(CRUCE[[#This Row],[DIFERENCIA2]]>0, "SOBRANTE", "FALTANTE"))) -> PENDIENTE | R12: --- | S12: e797b998-c5c4-40ab-8ddd-ef25fdf495fb
A13: PASILLO 1 | B13: AP-01-015-1 | H13: =_xlfn.XLOOKUP(CRUCE[[#This Row],[Ubicacion]],Registros[Ubicacion],Registros[Codigo], "") | I13: =_xlfn.XLOOKUP(CRUCE[[#This Row],[Ubicacion]],Registros[Ubicacion],Registros[Total], "") | J13: =_xlfn.XLOOKUP(CRUCE[[#This Row],[Ubicacion]],Registros[Ubicacion],Registros[UMA], "") | K13: =IF(CRUCE[[#This Row],[TOTAL]]="","",CRUCE[[#This Row],[TOTAL]]-CRUCE[[#This Row],[BULTOS]]) | L13: =IF(CRUCE[[#This Row],[TOTAL]]="", "PENDIENTE", IF(CRUCE[[#This Row],[Diferencia]]=0, "CUADRADO", IF(CRUCE[[#This Row],[Diferencia]]>0, "SOBRANTE", "FALTANTE"))) -> PENDIENTE | M13: =IF(CRUCE[[#This Row],[Diferencia]]="","",IF(CRUCE[[#This Row],[Diferencia]]=0,"OK","RECONTEO")) | N13: =_xlfn.XLOOKUP(CRUCE[[#This Row],[Ubicacion]],Registros[Ubicacion],Registros[Codigo], "") | Q13: =IF(CRUCE[[#This Row],[TOTAL2]]="", "PENDIENTE", IF(CRUCE[[#This Row],[DIFERENCIA2]]=0, "CUADRADO", IF(CRUCE[[#This Row],[DIFERENCIA2]]>0, "SOBRANTE", "FALTANTE"))) -> PENDIENTE | R13: --- | S13: 264348ae-3284-4b49-8ebe-1efa0358014b
A14: PASILLO 1 | B14: AP-01-016-1 | C14: 8325084 | D14: 67751851006622 | E14: INSE. SAP. MAT MOS Y ZANC BO 360ML 12UND | F14: 60 | G14: CJA | H14: =_xlfn.XLOOKUP(CRUCE[[#This Row],[Ubicacion]],Registros[Ubicacion],Registros[Codigo], "") | I14: =_xlfn.XLOOKUP(CRUCE[[#This Row],[Ubicacion]],Registros[Ubicacion],Registros[Total], "") | J14: =_xlfn.XLOOKUP(CRUCE[[#This Row],[Ubicacion]],Registros[Ubicacion],Registros[UMA], "") | K14: =IF(CRUCE[[#This Row],[TOTAL]]="","",CRUCE[[#This Row],[TOTAL]]-CRUCE[[#This Row],[BULTOS]]) | L14: =IF(CRUCE[[#This Row],[TOTAL]]="", "PENDIENTE", IF(CRUCE[[#This Row],[Diferencia]]=0, "CUADRADO", IF(CRUCE[[#This Row],[Diferencia]]>0, "SOBRANTE", "FALTANTE"))) -> PENDIENTE | M14: =IF(CRUCE[[#This Row],[Diferencia]]="","",IF(CRUCE[[#This Row],[Diferencia]]=0,"OK","RECONTEO")) | N14: =_xlfn.XLOOKUP(CRUCE[[#This Row],[Ubicacion]],Registros[Ubicacion],Registros[Codigo], "") | Q14: =IF(CRUCE[[#This Row],[TOTAL2]]="", "PENDIENTE", IF(CRUCE[[#This Row],[DIFERENCIA2]]=0, "CUADRADO", IF(CRUCE[[#This Row],[DIFERENCIA2]]>0, "SOBRANTE", "FALTANTE"))) -> PENDIENTE | R14: --- | S14: 19493bac-2d77-4dc7-b666-d88345e9ad66
